<mujoco>
  <compiler angle="degree"/>
  <option timestep="0.01" gravity="0 0 -9.81" integrator="RK4"/>

  <worldbody>
    <!-- Ground Plane -->
    <geom name="floor" type="plane" size="10 10 0.1" rgba="0.8 0.8 0.8 1"/>

    <!-- Lead Dancer -->
    <body name="lead" pos="-1 0 0.05" euler="0 0 0.0">
      <!-- Ellipsoid for Lead Dancer with Transparency -->
      <geom name="lead_geom" type="ellipsoid" size="0.15 0.25 0.05" rgba="0 0 1 0.5" density="850"/>
      
      <!-- Slider joint allowing translation along X-axis -->
      <joint name="lead_slide_x" type="slide" axis="1 0 0" pos="0 0 0.05" limited="true" range="0.0 2.0" damping="0.01"/>
      
      <!-- Slider joint allowing translation along Y-axis -->
      <joint name="lead_slide_y" type="slide" axis="0 1 0" pos="0 0 0.05" limited="true" range="-0.5 0.5" damping="0.01"/>
      
      <!-- Hinge joint allowing rotation around Z-axis with range of ±180° -->
      <joint name="lead_hinge_z" type="hinge" axis="0 0 1" pos="0 0 0.05" stiffness="2" damping=".1"/>
      
      <!-- Sites for Lead Dancer -->
      <site name="lead_cg" pos="0 0 0.0"/>
      <site name="lead_left_shoulder" pos="0 -0.25 0.0"/>
      <site name="lead_right_shoulder" pos="0 0.25 0.0"/>
      <site name="lead_nose" pos="0.5 0 0.0" size="0.02" rgba="1 1 0 1"/> <!-- Nose site -->

    </body>

    <!-- Follow Dancer -->
    <body name="follow" pos="1 0 0.05" euler="0 0 180.0">
      <!-- Ellipsoid for Follow Dancer with Transparency -->
      <geom name="follow_geom" type="ellipsoid" size="0.12 0.20 0.05" rgba="0.5 0 0.5 0.5" density="650"/>
      
      <!-- Slider joint allowing translation along X-axis -->
      <joint name="follow_slide_x" type="slide" axis="1 0 0" pos="0 0 0.05" limited="true" range="0.0 2.0" damping="0.01"/>
      
      <!-- Slider joint allowing translation along Y-axis -->
      <joint name="follow_slide_y" type="slide" axis="0 1 0" pos="0 0 0.05" limited="true" range="-0.5 0.5" damping="0.01"/>
      
      <!-- Hinge joint allowing rotation around Z-axis (no range for follow dancer) -->
      <joint name="follow_hinge_z" type="hinge" axis="0 0 1" pos="0 0 0.05" damping="0.05"/>
      
      <!-- Sites for Follow Dancer -->
      <site name="follow_cg" pos="0 0 0.0"/>
      <site name="follow_left_shoulder" pos="0 -0.2 0.0"/>
      <site name="follow_right_shoulder" pos="0 0.2 0.0"/>
      <site name="follow_nose" pos="0.5 0 0.0" size="0.02" rgba="1 1 0 1"/> <!-- Nose site -->

    </body>

    <!-- Salsa Coordinate Grid -->
    <site name="slot1" pos="-1.0 0 0.001" size="0.02" rgba="1 0 0 1"/>
    <site name="slot2" pos="-0.5 0 0.001" size="0.02" rgba="1 0 0 1"/>
    <site name="slot3" pos="0.0 0 0.001" size="0.02" rgba="1 0 0 1"/>
    <site name="slot4" pos="0.5 0 0.001" size="0.02" rgba="1 0 0 1"/>
    <site name="slot5" pos="1.0 0 0.001" size="0.02" rgba="1 0 0 1"/>

    <!-- Left Rail -->
    <site name="left1" pos="-1.0 -0.5 0.001" size="0.02" rgba="0 0 1 1"/>
    <site name="left2" pos="-0.5 -0.5 0.001" size="0.02" rgba="0 0 1 1"/>
    <site name="left3" pos="0.0 -0.5 0.001" size="0.02" rgba="0 0 1 1"/>
    <site name="left4" pos="0.5 -0.5 0.001" size="0.02" rgba="0 0 1 1"/>
    <site name="left5" pos="1.0 -0.5 0.001" size="0.02" rgba="0 0 1 1"/>

    <!-- Right Rail -->
    <site name="right1" pos="-1.0 0.5 0.001" size="0.02" rgba="0 1 0 1"/>
    <site name="right2" pos="-0.5 0.5 0.001" size="0.02" rgba="0 1 0 1"/>
    <site name="right3" pos="0.0 0.5 0.001" size="0.02" rgba="0 1 0 1"/>
    <site name="right4" pos="0.5 0.5 0.001" size="0.02" rgba="0 1 0 1"/>
    <site name="right5" pos="1.0 0.5 0.001" size="0.02" rgba="0 1 0 1"/>
  </worldbody>

  <actuator>
    <!-- General Force Actuators for Lead -->
    <general name="lead_forward_force" site="lead_cg" ctrllimited="true" ctrlrange="-10 10" forcelimited="true" forcerange="-10 10" gear="1 0 0 0 0 0"/>
    <general name="lead_lateral_force" site="lead_cg" ctrllimited="true" ctrlrange="-10 10" forcelimited="true" forcerange="-10 10" gear="0 1 0 0 0 0"/>
    <general name="lead_moment" site="lead_cg" ctrllimited="true" ctrlrange="-2 2" forcelimited="true" forcerange="-2 2" gear="0 0 0 0 0 1"/>

    <!-- General Force Actuators for Follow -->
    <general name="follow_forward_force" site="follow_cg" ctrllimited="true" ctrlrange="-10 10" forcelimited="true" forcerange="-10 10" gear="1 0 0 0 0 0"/>
    <general name="follow_lateral_force" site="follow_cg" ctrllimited="true" ctrlrange="-10 10" forcelimited="true" forcerange="-10 10" gear="0 1 0 0 0 0"/>
    <general name="follow_moment" site="follow_cg" ctrllimited="true" ctrlrange="-2 2" forcelimited="true" forcerange="-2 2" gear="0 0 0 0 0 1"/>
  </actuator>

  <!-- Tendon Elements: Representing Elastic String/ Rubber Band Between Lead and Follow -->
  <tendon>
      <spatial name="alignment_spring" springlength="0" stiffness="10" damping="3">
          <site site="lead_nose"/>
          <site site="follow_cg"/>
      </spatial>
  </tendon>

</mujoco>

<key qpos='-1.25553e-10 0.424585 0.0499978 1 -6.30484e-05 5.8393e-12 -1.00223e-06 8.18356e-09 1.17528 0.0499978 1 0.000227857 2.27094e-10 1.89271e-06'/>
